Workbook

Sheet 0_Теория
A1: Занятие 8. Фильтрация, сортировка и вычисляемые столбцы
A3: Тема | B3: Как фильтровать строки, сортировать таблицу и создавать новые столбцы в Excel и Python.
A4: Зачем это нужно | B4: Фильтрация помогает быстро находить нужные строки, сортировка — видеть приоритеты, а новые столбцы — делать расчёты по данным.
A5: Ключевые методы Python | B5: pd.read_excel(), df[условие], &, sort_values(), df["new_column"] = ..., sum().
A6: Ключевые действия в Excel | B6: Автофильтр, IF+AND для проверки условий, сортировка по столбцу, формулы для расчёта revenue.
A7: Мини-проект урока | B7: Посчитать выручку по заказам, найти крупные заказы и отсортировать их по убыванию.

Sheet sales_data
A1: Лист sales_data — исходные данные для ноутбука
A2: order_id | B2: date | C2: day | D2: month | E2: manager | F2: city | G2: region | H2: category | I2: product | J2: client_type | K2: quantity | L2: price_per_unit | M2: revenue | N2: channel | O2: status
A3: 85 | B3: 45881 | C3: 12 | D3: Август | E3: Владимир | F3: Уфа | G3: Приволжский | H3: Аксессуары | I3: Screen Protector | J3: Опт | K3: 20 | L3: 800 | M3: 16000 | N3: Интернет-магазин | O3: В пути
A4: 225 | B4: 45697 | C4: 9 | D4: Февраль | E4: Сергей | F4: Казань | G4: Приволжский | H4: Аксессуары | I4: Screen Protector | J4: Опт | K4: 25 | L4: 800 | M4: 20000 | N4: Офлайн-точка | O4: Доставлен
A5: 332 | B5: 45941 | C5: 11 | D5: Октябрь | E5: Борис | F5: Омск | G5: Сибирский | H5: Аксессуары | I5: Screen Protector | J5: Опт | K5: 5 | L5: 800 | M5: 4000 | N5: Офлайн-точка | O5: В пути
A6: 430 | B6: 45746 | C6: 30 | D6: Март | E6: Светлана | F6: Новосибирск | G6: Сибирский | H6: Аксессуары | I6: Screen Protector | J6: Опт | K6: 42 | L6: 800 | M6: 33600 | N6: Интернет-магазин | O6: Отменён
A7: 459 | B7: 45856 | C7: 18 | D7: Июль | E7: Мария | F7: Нижний Новгород | G7: Приволжский | H7: Аксессуары | I7: Screen Protector | J7: Опт | K7: 38 | L7: 800 | M7: 30400 | N7: Офлайн-точка | O7: Доставлен
A8: 570 | B8: 45766 | C8: 19 | D8: Апрель | E8: Ксения | F8: Москва | G8: Центральный | H8: Аксессуары | I8: Screen Protector | J8: Опт | K8: 46 | L8: 800 | M8: 36800 | N8: Интернет-магазин | O8: В пути
A9: 639 | B9: 45901 | C9: 1 | D9: Сентябрь | E9: Павел | F9: Пермь | G9: Приволжский | H9: Аксессуары | I9: Screen Protector | J9: Опт | K9: 13 | L9: 800 | M9: 10400 | N9: Интернет-магазин | O9: Отменён
A10: 665 | B10: 45809 | C10: 1 | D10: Июнь | E10: Владимир | F10: Екатеринбург | G10: Уральский | H10: Аксессуары | I10: Screen Protector | J10: Опт | K10: 5 | L10: 800 | M10: 4000 | N10: Офлайн-точка | O10: Отменён
A11: 746 | B11: 45979 | C11: 18 | D11: Ноябрь | E11: Павел | F11: Воронеж | G11: Центральный | H11: Аксессуары | I11: Screen Protector | J11: Опт | K11: 31 | L11: 800 | M11: 24800 | N11: Интернет-магазин | O11: Отменён
A12: 1035 | B12: 45812 | C12: 4 | D12: Июнь | E12: Борис | F12: Москва | G12: Центральный | H12: Аксессуары | I12: Screen Protector | J12: Опт | K12: 13 | L12: 800 | M12: 10400 | N12: Офлайн-точка | O12: Доставлен
A13: 1562 | B13: 45696 | C13: 8 | D13: Февраль | E13: Игорь | F13: Казань | G13: Приволжский | H13: Аксессуары | I13: Screen Protector | J13: Опт | K13: 34 | L13: 800 | M13: 27200 | N13: Интернет-магазин | O13: Отменён
A14: 1720 | B14: 45786 | C14: 9 | D14: Май | E14: Наталья | F14: Нижний Новгород | G14: Приволжский | H14: Аксессуары | I14: Screen Protector | J14: Опт | K14: 45 | L14: 800 | M14: 36000 | N14: Интернет-магазин | O14: В пути
... A5002: 180 | B5002: 45837 | C5002: 29 | D5002: Июнь | E5002: Алексей | F5002: Пермь | G5002: Приволжский | H5002: Серверы | I5002: Server Blade | J5002: Розница | K5002: 2 | L5002: 227200 | M5002: 454400 | N5002: Интернет-магазин | O5002: В пути

Sheet 1_Обзор
A1: Шаг 1. Загружаем таблицу и смотрим на её структуру
A3: Показатель | B3: Значение | D3: order_id | E3: month | F3: city | G3: category | H3: product | I3: quantity | J3: price | K3: manager | L3: channel
A4: Количество строк | B4: =COUNTA(sales_data!A3:A5002) -> 5000 | D4: =sales_data!A3 -> 85 | E4: =sales_data!D3 -> Август | F4: =sales_data!F3 -> Уфа | G4: =sales_data!H3 -> Аксессуары | H4: =sales_data!I3 -> Screen Protector | I4: =sales_data!K3 -> 20 | J4: =sales_data!L3 -> 800 | K4: =sales_data!E3 -> Владимир | L4: =sales_data!N3 -> Интернет-магазин
A5: Количество столбцов | B5: =COUNTA(sales_data!A2:'sales_data'!O2) -> 15 | D5: =sales_data!A4 -> 225 | E5: =sales_data!D4 -> Февраль | F5: =sales_data!F4 -> Казань | G5: =sales_data!H4 -> Аксессуары | H5: =sales_data!I4 -> Screen Protector | I5: =sales_data!K4 -> 25 | J5: =sales_data!L4 -> 800 | K5: =sales_data!E4 -> Сергей | L5: =sales_data!N4 -> Офлайн-точка
A6: Уникальных категорий | B6: =COUNTA(_xlfn.UNIQUE(sales_data!H3:H5002)) -> 6 | D6: =sales_data!A5 -> 332 | E6: =sales_data!D5 -> Октябрь | F6: =sales_data!F5 -> Омск | G6: =sales_data!H5 -> Аксессуары | H6: =sales_data!I5 -> Screen Protector | I6: =sales_data!K5 -> 5 | J6: =sales_data!L5 -> 800 | K6: =sales_data!E5 -> Борис | L6: =sales_data!N5 -> Офлайн-точка
A7: Есть ли онлайн-заказы? | B7: =IF(COUNTIF(sales_data!N3:N5002,"Интернет-магазин")>0,"Да","Нет") -> Да | D7: =sales_data!A6 -> 430 | E7: =sales_data!D6 -> Март | F7: =sales_data!F6 -> Новосибирск | G7: =sales_data!H6 -> Аксессуары | H7: =sales_data!I6 -> Screen Protector | I7: =sales_data!K6 -> 42 | J7: =sales_data!L6 -> 800 | K7: =sales_data!E6 -> Светлана | L7: =sales_data!N6 -> Интернет-магазин

Sheet 2_Фильтр_1
A1: Шаг 2. Фильтрация по одному условию: category == "Ноутбуки"
A3: order_id | B3: client | C3: city | D3: category | E3: product | F3: quantity | G3: price | H3: manager | I3: channel | J3: flag_ноутбуки | L3: order_id | M3: date | N3: day | O3: month | P3: manager | Q3: city | R3: region | S3: category | T3: product | U3: client_type | V3: quantity | W3: price_per_unit | X3: revenue | Y3: channel | Z3: status
A4: 201 | B4: ООО Альфа | C4: Москва | D4: Ноутбуки | E4: Notebook Air | F4: 2 | G4: 55000 | H4: Анна | I4: Онлайн | J4: =IF(D4="Ноутбуки","Да","Нет") -> Да | L4: =sales_data!A6 -> 430 | M4: =sales_data!B6 -> 45746 | N4: =sales_data!C6 -> 30 | O4: =sales_data!D6 -> Март | P4: =sales_data!E6 -> Светлана | Q4: =sales_data!F6 -> Новосибирск | R4: =sales_data!G6 -> Сибирский | S4: =sales_data!H6 -> Аксессуары | ... Z4: =sales_data!O6 -> Отменён
A5: 202 | B5: ООО Бета | C5: Санкт-Петербург | D5: Мониторы | E5: Monitor 27 | F5: 1 | G5: 23000 | H5: Борис | I5: Офлайн | J5: =IF(D5="Ноутбуки","Да","Нет") -> Нет | L5: =sales_data!A7 -> 459 | M5: =sales_data!B7 -> 45856 | N5: =sales_data!C7 -> 18 | O5: =sales_data!D7 -> Июль | P5: =sales_data!E7 -> Мария | Q5: =sales_data!F7 -> Нижний Новгород | R5: =sales_data!G7 -> Приволжский | S5: =sales_data!H7 -> Аксессуары | ... Z5: =sales_data!O7 -> Доставлен
A6: 203 | B6: ИП Гамма | C6: Москва | D6: Ноутбуки | E6: Notebook Pro | F6: 3 | G6: 72000 | H6: Анна | I6: Онлайн | J6: =IF(D6="Ноутбуки","Да","Нет") -> Да | L6: =sales_data!A8 -> 570 | M6: =sales_data!B8 -> 45766 | N6: =sales_data!C8 -> 19 | O6: =sales_data!D8 -> Апрель | P6: =sales_data!E8 -> Ксения | Q6: =sales_data!F8 -> Москва | R6: =sales_data!G8 -> Центральный | S6: =sales_data!H8 -> Аксессуары | ... Z6: =sales_data!O8 -> В пути
A7: 204 | B7: ООО Дельта | C7: Казань | D7: Периферия | E7: Mouse Pro | F7: 5 | G7: 2500 | H7: Виктор | I7: Маркетплейс | J7: =IF(D7="Ноутбуки","Да","Нет") -> Нет | L7: =sales_data!A10 -> 665 | M7: =sales_data!B10 -> 45809 | N7: =sales_data!C10 -> 1 | O7: =sales_data!D10 -> Июнь | P7: =sales_data!E10 -> Владимир | Q7: =sales_data!F10 -> Екатеринбург | R7: =sales_data!G10 -> Уральский | S7: =sales_data!H10 -> Аксессуары | ... Z7: =sales_data!O10 -> Отменён
A8: 205 | B8: ООО Эпсилон | C8: Москва | D8: Мониторы | E8: Monitor 24 | F8: 2 | G8: 18000 | H8: Анна | I8: Онлайн | J8: =IF(D8="Ноутбуки","Да","Нет") -> Нет | L8: =sales_data!A19 -> 2086 | M8: =sales_data!B19 -> 45742 | N8: =sales_data!C19 -> 26 | O8: =sales_data!D19 -> Март | P8: =sales_data!E19 -> Игорь | Q8: =sales_data!F19 -> Казань | R8: =sales_data!G19 -> Приволжский | S8: =sales_data!H19 -> Аксессуары | ... Z8: =sales_data!O19 -> Доставлен
A9: 206 | B9: ИП Жасмин | C9: Екатеринбург | D9: Ноутбуки | E9: Notebook Lite | F9: 1 | G9: 49000 | H9: Борис | I9: Офлайн | J9: =IF(D9="Ноутбуки","Да","Нет") -> Да | L9: =sales_data!A28 -> 3062 | M9: =sales_data!B28 -> 45664 | N9: =sales_data!C28 -> 7 | O9: =sales_data!D28 -> Январь | P9: =sales_data!E28 -> Татьяна | Q9: =sales_data!F28 -> Воронеж | R9: =sales_data!G28 -> Центральный | S9: =sales_data!H28 -> Аксессуары | ... Z9: =sales_data!O28 -> В пути
A10: 207 | B10: ООО Зета | C10: Москва | D10: Периферия | E10: Keyboard X | F10: 4 | G10: 4000 | H10: Виктор | I10: Онлайн | J10: =IF(D10="Ноутбуки","Да","Нет") -> Нет | L10: =sales_data!A33 -> 3945 | M10: =sales_data!B33 -> 45787 | N10: =sales_data!C33 -> 10 | O10: =sales_data!D33 -> Май | P10: =sales_data!E33 -> Мария | Q10: =sales_data!F33 -> Воронеж | R10: =sales_data!G33 -> Центральный | S10: =sales_data!H33 -> Аксессуары | ... Z10: =sales_data!O33 -> В пути
A11: 208 | B11: ООО Ита | C11: Новосибирск | D11: Ноутбуки | E11: Notebook Air | F11: 2 | G11: 55000 | H11: Анна | I11: Маркетплейс | J11: =IF(D11="Ноутбуки","Да","Нет") -> Да | L11: =sales_data!A36 -> 4279 | M11: =sales_data!B36 -> 45810 | N11: =sales_data!C36 -> 2 | O11: =sales_data!D36 -> Июнь | P11: =sales_data!E36 -> Игорь | Q11: =sales_data!F36 -> Омск | R11: =sales_data!G36 -> Сибирский | S11: =sales_data!H36 -> Аксессуары | ... Z11: =sales_data!O36 -> В пути
A12: 209 | B12: ООО Каппа | C12: Москва | D12: Ноутбуки | E12: Notebook Start | F12: 1 | G12: 43000 | H12: Борис | I12: Офлайн | J12: =IF(D12="Ноутбуки","Да","Нет") -> Да | L12: =sales_data!A39 -> 500 | M12: =sales_data!B39 -> 45996 | N12: =sales_data!C39 -> 5 | O12: =sales_data!D39 -> Декабрь | P12: =sales_data!E39 -> Борис | Q12: =sales_data!F39 -> Ростов-на-Дону | R12: =sales_data!G39 -> Южный | S12: =sales_data!H39 -> Аксессуары | ... Z12: =sales_data!O39 -> Отменён
L13: =sales_data!A52 -> 1518 | M13: =sales_data!B52 -> 45836 | N13: =sales_data!C52 -> 28 | O13: =sales_data!D52 -> Июнь | P13: =sales_data!E52 -> Ксения | Q13: =sales_data!F52 -> Москва | R13: =sales_data!G52 -> Центральный | S13: =sales_data!H52 -> Аксессуары | ... Z13: =sales_data!O52 -> Доставлен
L14: =sales_data!A57 -> 1911 | M14: =sales_data!B57 -> 45741 | N14: =sales_data!C57 -> 25 | O14: =sales_data!D57 -> Март | P14: =sales_data!E57 -> Ольга | Q14: =sales_data!F57 -> Ростов-на-Дону | R14: =sales_data!G57 -> Южный | S14: =sales_data!H57 -> Аксессуары | ... Z14: =sales_data!O57 -> Доставлен
L15: =sales_data!A64 -> 2460 | M15: =sales_data!B64 -> 45698 | N15: =sales_data!C64 -> 10 | O15: =sales_data!D64 -> Февраль | P15: =sales_data!E64 -> Светлана | Q15: =sales_data!F64 -> Омск | R15: =sales_data!G64 -> Сибирский | S15: =sales_data!H64 -> Аксессуары | ... Z15: =sales_data!O64 -> В пути
L16: =sales_data!A72 -> 2688 | M16: =sales_data!B72 -> 45791 | N16: =sales_data!C72 -> 14 | O16: =sales_data!D72 -> Май | P16: =sales_data!E72 -> Алексей | Q16: =sales_data!F72 -> Краснодар | R16: =sales_data!G72 -> Южный | S16: =sales_data!H72 -> Аксессуары | ... Z16: =sales_data!O72 -> В пути
L17: =sales_data!A80 -> 3183 | M17: =sales_data!B80 -> 45854 | N17: =sales_data!C80 -> 16 | O17: =sales_data!D80 -> Июль | P17: =sales_data!E80 -> Борис | Q17: =sales_data!F80 -> Уфа | R17: =sales_data!G80 -> Приволжский | S17: =sales_data!H80 -> Аксессуары | ... Z17: =sales_data!O80 -> В пути
L18: =sales_data!A85 -> 3892 | M18: =sales_data!B85 -> 45812 | N18: =sales_data!C85 -> 4 | O18: =sales_data!D85 -> Июнь | P18: =sales_data!E85 -> Наталья | Q18: =sales_data!F85 -> Санкт-Петербург | R18: =sales_data!G85 -> Северо-Западный | S18: =sales_data!H85 -> Аксессуары | ... Z18: =sales_data!O85 -> В пути
L19: =sales_data!A90 -> 4115 | M19: =sales_data!B90 -> 45966 | N19: =sales_data!C90 -> 5 | O19: =sales_data!D90 -> Ноябрь | P19: =sales_data!E90 -> Дмитрий | Q19: =sales_data!F90 -> Челябинск | R19: =sales_data!G90 -> Уральский | S19: =sales_data!H90 -> Аксессуары | ... Z19: =sales_data!O90 -> В пути
L20: =sales_data!A109 -> 246 | M20: =sales_data!B109 -> 45739 | N20: =sales_data!C109 -> 23 | O20: =sales_data!D109 -> Март | P20: =sales_data!E109 -> Владимир | Q20: =sales_data!F109 -> Краснодар | R20: =sales_data!G109 -> Южный | S20: =sales_data!H109 -> Аксессуары | ... Z20: =sales_data!O109 -> Отменён
L21: =sales_data!A117 -> 558 | M21: =sales_data!B117 -> 45858 | N21: =sales_data!C117 -> 20 | O21: =sales_data!D117 -> Июль | P21: =sales_data!E117 -> Наталья | Q21: =sales_data!F117 -> Красноярск | R21: =sales_data!G117 -> Сибирский | S21: =sales_data!H117 -> Аксессуары | ... Z21: =sales_data!O117 -> Доставлен
L22: =sales_data!A125 -> 729 | M22: =sales_data!B125 -> 45725 | N22: =sales_data!C125 -> 9 | O22: =sales_data!D125 -> Март | P22: =sales_data!E125 -> Дмитрий | Q22: =sales_data!F125 -> Москва | R22: =sales_data!G125 -> Центральный | S22: =sales_data!H125 -> Аксессуары | ... Z22: =sales_data!O125 -> В пути
L23: =sales_data!A130 -> 1037 | M23: =sales_data!B130 -> 45672 | N23: =sales_data!C130 -> 15 | O23: =sales_data!D130 -> Январь | P23: =sales_data!E130 -> Ксения | Q23: =sales_data!F130 -> Красноярск | R23: =sales_data!G130 -> Сибирский | S23: =sales_data!H130 -> Аксессуары | ... Z23: =sales_data!O130 -> Отменён
L24: =sales_data!A135 -> 1493 | M24: =sales_data!B135 -> 45949 | N24: =sales_data!C135 -> 19 | O24: =sales_data!D135 -> Октябрь | P24: =sales_data!E135 -> Борис | Q24: =sales_data!F135 -> Казань | R24: =sales_data!G135 -> Приволжский | S24: =sales_data!H135 -> Аксессуары | ... Z24: =sales_data!O135 -> Доставлен
L25: =sales_data!A136 -> 1553 | M25: =sales_data!B136 -> 45682 | N25: =sales_data!C136 -> 25 | O25: =sales_data!D136 -> Январь | P25: =sales_data!E136 -> Сергей | Q25: =sales_data!F136 -> Самара | R25: =sales_data!G136 -> Приволжский | S25: =sales_data!H136 -> Аксессуары | ... Z25: =sales_data!O136 -> В пути
L26: =sales_data!A150 -> 2320 | M26: =sales_data!B150 -> 45778 | N26: =sales_data!C150 -> 1 | O26: =sales_data!D150 -> Май | P26: =sales_data!E150 -> Владимир | Q26: =sales_data!F150 -> Самара | R26: =sales_data!G150 -> Приволжский | S26: =sales_data!H150 -> Аксессуары | ... Z26: =sales_data!O150 -> Доставлен
L27: =sales_data!A158 -> 2770 | M27: =sales_data!B158 -> 45974 | N27: =sales_data!C158 -> 13 | O27: =sales_data!D158 -> Ноябрь | P27: =sales_data!E158 -> Ольга | Q27: =sales_data!F158 -> Нижний Новгород | R27: =sales_data!G158 -> Приволжский | S27: =sales_data!H158 -> Аксессуары | ... Z27: =sales_data!O158 -> В пути
L28: =sales_data!A160 -> 2772 | M28: =sales_data!B160 -> 45944 | N28: =sales_data!C160 -> 14 | O28: =sales_data!D160 -> Октябрь | P28: =sales_data!E160 -> Игорь | Q28: =sales_data!F160 -> Ростов-на-Дону | R28: =sales_data!G160 -> Южный | S28: =sales_data!H160 -> Аксессуары | ... Z28: =sales_data!O160 -> Доставлен
L29: =sales_data!A166 -> 3135 | M29: =sales_data!B166 -> 45926 | N29: =sales_data!C166 -> 26 | O29: =sales_data!D166 -> Сентябрь | P29: =sales_data!E166 -> Светлана | Q29: =sales_data!F166 -> Москва | R29: =sales_data!G166 -> Центральный | S29: =sales_data!H166 -> Аксессуары | ... Z29: =sales_data!O166 -> Доставлен
L30: =sales_data!A169 -> 3434 | M30: =sales_data!B169 -> 45910 | N30: =sales_data!C169 -> 10 | O30: =sales_data!D169 -> Сентябрь | P30: =sales_data!E169 -> Наталья | Q30: =sales_data!F169 -> Краснодар | R30: =sales_data!G169 -> Южный | S30: =sales_data!H169 -> Аксессуары | ... Z30: =sales_data!O169 -> Отменён
L31: =sales_data!A174 -> 3822 | M31: =sales_data!B174 -> 45765 | N31: =sales_data!C174 -> 18 | O31: =sales_data!D174 -> Апрель | P31: =sales_data!E174 -> Анна | Q31: =sales_data!F174 -> Нижний Новгород | R31: =sales_data!G174 -> Приволжский | S31: =sales_data!H174 -> Аксессуары | ... Z31: =sales_data!O174 -> Отменён
L32: =sales_data!A175 -> 3872 | M32: =sales_data!B175 -> 45676 | N32: =sales_data!C175 -> 19 | O32: =sales_data!D175 -> Январь | P32: =sales_data!E175 -> Ольга | Q32: =sales_data!F175 -> Челябинск | R32: =sales_data!G175 -> Уральский | S32: =sales_data!H175 -> Аксессуары | ... Z32: =sales_data!O175 -> Отменён
L33: =sales_data!A181 -> 4331 | M33: =sales_data!B181 -> 45678 | N33: =sales_data!C181 -> 21 | O33: =sales_data!D181 -> Январь | P33: =sales_data!E181 -> Борис | Q33: =sales_data!F181 -> Екатеринбург | R33: =sales_data!G181 -> Уральский | S33: =sales_data!H181 -> Аксессуары | ... Z33: =sales_data!O181 -> Отменён
L34: =sales_data!A187 -> 4448 | M34: =sales_data!B187 -> 45966 | N34: =sales_data!C187 -> 5 | O34: =sales_data!D187 -> Ноябрь | P34: =sales_data!E187 -> Анна | Q34: =sales_data!F187 -> Екатеринбург | R34: =sales_data!G187 -> Уральский | S34: =sales_data!H187 -> Аксессуары | ... Z34: =sales_data!O187 -> Отменён
L35: =sales_data!A197 -> 4708 | M35: =sales_data!B197 -> 45686 | N35: =sales_data!C197 -> 29 | O35: =sales_data!D197 -> Январь | P35: =sales_data!E197 -> Ксения | Q35: =sales_data!F197 -> Челябинск | R35: =sales_data!G197 -> Уральский | S35: =sales_data!H197 -> Аксессуары | ... Z35: =sales_data!O197 -> Отменён
L36: =sales_data!A202 -> 4969 | M36: =sales_data!B202 -> 45844 | N36: =sales_data!C202 -> 6 | O36: =sales_data!D202 -> Июль | P36: =sales_data!E202 -> Анна | Q36: =sales_data!F202 -> Екатеринбург | R36: =sales_data!G202 -> Уральский | S36: =sales_data!H202 -> Аксессуары | ... Z36: =sales_data!O202 -> Отменён
L37: =sales_data!A204 -> 4996 | M37: =sales_data!B204 -> 45818 | N37: =sales_data!C204 -> 10 | O37: =sales_data!D204 -> Июнь | P37: =sales_data!E204 -> Владимир | Q37: =sales_data!F204 -> Омск | R37: =sales_data!G204 -> Сибирский | S37: =sales_data!H204 -> Аксессуары | ... Z37: =sales_data!O204 -> Доставлен
L38: =sales_data!A206 -> 7 | M38: =sales_data!B206 -> 45808 | N38: =sales_data!C206 -> 31 | O38: =sales_data!D206 -> Май | P38: =sales_data!E206 -> Владимир | Q38: =sales_data!F206 -> Ростов-на-Дону | R38: =sales_data!G206 -> Южный | S38: =sales_data!H206 -> Аксессуары | ... Z38: =sales_data!O206 -> Отменён
L39: =sales_data!A225 -> 2078 | M39: =sales_data!B225 -> 46007 | N39: =sales_data!C225 -> 16 | O39: =sales_data!D225 -> Декабрь | P39: =sales_data!E225 -> Владимир | Q39: =sales_data!F225 -> Уфа | R39: =sales_data!G225 -> Приволжский | S39: =sales_data!H225 -> Аксессуары | ... Z39: =sales_data!O225 -> Доставлен
L40: =sales_data!A230 -> 2532 | M40: =sales_data!B230 -> 45877 | N40: =sales_data!C230 -> 8 | O40: =sales_data!D230 -> Август | P40: =sales_data!E230 -> Павел | Q40: =sales_data!F230 -> Новосибирск | R40: =sales_data!G230 -> Сибирский | S40: =sales_data!H230 -> Аксессуары | ... Z40: =sales_data!O230 -> Отменён
L41: =sales_data!A234 -> 3074 | M41: =sales_data!B234 -> 45992 | N41: =sales_data!C234 -> 1 | O41: =sales_data!D234 -> Декабрь | P41: =sales_data!E234 -> Анна | Q41: =sales_data!F234 -> Москва | R41: =sales_data!G234 -> Центральный | S41: =sales_data!H234 -> Аксессуары | ... Z41: =sales_data!O234 -> Отменён
...

Sheet 3_Фильтр_2
A1: Шаг 3. Фильтрация по двум условиям: city == "Москва" и channel == "Онлайн"
A3: order_id | B3: client | C3: city | D3: category | E3: product | F3: quantity | G3: price | H3: manager | I3: channel | J3: flag_москва_онлайн | L3: order_id | M3: date | N3: day | O3: month | P3: manager | Q3: city | R3: region | S3: category | T3: product | U3: client_type | V3: quantity | W3: price_per_unit | X3: revenue | Y3: channel | Z3: status
A4: 201 | B4: ООО Альфа | C4: Москва | D4: Ноутбуки | E4: Notebook Air | F4: 2 | G4: 55000 | H4: Анна | I4: Онлайн | J4: =IF(AND(C4="Москва",I4="Онлайн"),"Да","Нет") -> Да | L4: =sales_data!A3 -> 85 | M4: =sales_data!B3 -> 45881 | N4: =sales_data!C3 -> 12 | O4: =sales_data!D3 -> Август | P4: =sales_data!E3 -> Владимир | Q4: =sales_data!F3 -> Уфа | R4: =sales_data!G3 -> Приволжский | S4: =sales_data!H3 -> Аксессуары | ... Z4: =sales_data!O3 -> В пути
A5: 202 | B5: ООО Бета | C5: Санкт-Петербург | D5: Мониторы | E5: Monitor 27 | F5: 1 | G5: 23000 | H5: Борис | I5: Офлайн | J5: =IF(AND(C5="Москва",I5="Онлайн"),"Да","Нет") -> Нет | L5: =sales_data!A73 -> 2784 | M5: =sales_data!B73 -> 45961 | N5: =sales_data!C73 -> 31 | O5: =sales_data!D73 -> Октябрь | P5: =sales_data!E73 -> Ксения | Q5: =sales_data!F73 -> Пермь | R5: =sales_data!G73 -> Приволжский | S5: =sales_data!H73 -> Аксессуары | ... Z5: =sales_data!O73 -> В пути
A6: 203 | B6: ИП Гамма | C6: Москва | D6: Ноутбуки | E6: Notebook Pro | F6: 3 | G6: 72000 | H6: Анна | I6: Онлайн | J6: =IF(AND(C6="Москва",I6="Онлайн"),"Да","Нет") -> Да | L6: =sales_data!A79 -> 3175 | M6: =sales_data!B79 -> 45829 | N6: =sales_data!C79 -> 21 | O6: =sales_data!D79 -> Июнь | P6: =sales_data!E79 -> Мария | Q6: =sales_data!F79 -> Екатеринбург | R6: =sales_data!G79 -> Уральский | S6: =sales_data!H79 -> Аксессуары | ... Z6: =sales_data!O79 -> В пути
A7: 204 | B7: ООО Дельта | C7: Казань | D7: Периферия | E7: Mouse Pro | F7: 5 | G7: 2500 | H7: Виктор | I7: Маркетплейс | J7: =IF(AND(C7="Москва",I7="Онлайн"),"Да","Нет") -> Нет | L7: =sales_data!A103 -> 59 | M7: =sales_data!B103 -> 45804 | N7: =sales_data!C103 -> 27 | O7: =sales_data!D103 -> Май | P7: =sales_data!E103 -> Дмитрий | Q7: =sales_data!F103 -> Нижний Новгород | R7: =sales_data!G103 -> Приволжский | S7: =sales_data!H103 -> Аксессуары | ... Z7: =sales_data!O103 -> В пути
A8: 205 | B8: ООО Эпсилон | C8: Москва | D8: Мониторы | E8: Monitor 24 | F8: 2 | G8: 18000 | H8: Анна | I8: Онлайн | J8: =IF(AND(C8="Москва",I8="Онлайн"),"Да","Нет") -> Да | L8: =sales_data!A110 -> 248 | M8: =sales_data!B110 -> 45892 | N8: =sales_data!C110 -> 23 | O8: =sales_data!D110 -> Август | P8: =sales_data!E110 -> Дмитрий | Q8: =sales_data!F110 -> Новосибирск | R8: =sales_data!G110 -> Сибирский | S8: =sales_data!H110 -> Аксессуары | ... Z8: =sales_data!O110 -> В пути
A9: 206 | B9: ИП Жасмин | C9: Екатеринбург | D9: Ноутбуки | E9: Notebook Lite | F9: 1 | G9: 49000 | H9: Борис | I9: Офлайн | J9: =IF(AND(C9="Москва",I9="Онлайн"),"Да","Нет") -> Нет | L9: =sales_data!A146 -> 2192 | M9: =sales_data!B146 -> 45708 | N9: =sales_data!C146 -> 20 | O9: =sales_data!D146 -> Февраль | P9: =sales_data!E146 -> Павел | Q9: =sales_data!F146 -> Красноярск | R9: =sales_data!G146 -> Сибирский | S9: =sales_data!H146 -> Аксессуары | ... Z9: =sales_data!O146 -> Отменён
A10: 207 | B10: ООО Зета | C10: Москва | D10: Периферия | E10: Keyboard X | F10: 4 | G10: 4000 | H10: Виктор | I10: Онлайн | J10: =IF(AND(C10="Москва",I10="Онлайн"),"Да","Нет") -> Да | L10: =sales_data!A157 -> 2757 | M10: =sales_data!B157 -> 45711 | N10: =sales_data!C157 -> 23 | O10: =sales_data!D157 -> Февраль | P10: =sales_data!E157 -> Дмитрий | Q10: =sales_data!F157 -> Нижний Новгород | R10: =sales_data!G157 -> Приволжский | S10: =sales_data!H157 -> Аксессуары | ... Z10: =sales_data!O157 -> Доставлен
A11: 208 | B11: ООО Ита | C11: Новосибирск | D11: Ноутбуки | E11: Notebook Air | F11: 2 | G11: 55000 | H11: Анна | I11: Маркетплейс | J11: =IF(AND(C11="Москва",I11="Онлайн"),"Да","Нет") -> Нет | L11: =sales_data!A209 -> 419 | M11: =sales_data!B209 -> 45980 | N11: =sales_data!C209 -> 19 | O11: =sales_data!D209 -> Ноябрь | P11: =sales_data!E209 -> Татьяна | Q11: =sales_data!F209 -> Санкт-Петербург | R11: =sales_data!G209 -> Северо-Западный | S11: =sales_data!H209 -> Аксессуары | ... Z11: =sales_data!O209 -> Доставлен
A12: 209 | B12: ООО Каппа | C12: Москва | D12: Ноутбуки | E12: Notebook Start | F12: 1 | G12: 43000 | H12: Борис | I12: Офлайн | J12: =IF(AND(C12="Москва",I12="Онлайн"),"Да","Нет") -> Нет | L12: =sales_data!A260 -> 423 | M12: =sales_data!B260 -> 45734 | N12: =sales_data!C260 -> 18 | O12: =sales_data!D260 -> Март | P12: =sales_data!E260 -> Анна | Q12: =sales_data!F260 -> Омск | R12: =sales_data!G260 -> Сибирский | S12: =sales_data!H260 -> Аксессуары | ... Z12: =sales_data!O260 -> В пути
L13: =sales_data!A332 -> 3847 | M13: =sales_data!B332 -> 45860 | N13: =sales_data!C332 -> 22 | O13: =sales_data!D332 -> Июль | P13: =sales_data!E332 -> Анна | Q13: =sales_data!F332 -> Челябинск | R13: =sales_data!G332 -> Уральский | S13: =sales_data!H332 -> Аксессуары | ... Z13: =sales_data!O332 -> Доставлен
L14: =sales_data!A347 -> 3212 | M14: =sales_data!B347 -> 46007 | N14: =sales_data!C347 -> 16 | O14: =sales_data!D347 -> Декабрь | P14: =sales_data!E347 -> Светлана | Q14: =sales_data!F347 -> Новосибирск | R14: =sales_data!G347 -> Сибирский | S14: =sales_data!H347 -> Аксессуары | ... Z14: =sales_data!O347 -> Доставлен
L15: =sales_data!A369 -> 1716 | M15: =sales_data!B369 -> 45782 | N15: =sales_data!C369 -> 5 | O15: =sales_data!D369 -> Май | P15: =sales_data!E369 -> Сергей | Q15: =sales_data!F369 -> Красноярск | R15: =sales_data!G369 -> Сибирский | S15: =sales_data!H369 -> Аксессуары | ... Z15: =sales_data!O369 -> В пути
L16: =sales_data!A417 -> 2806 | M16: =sales_data!B417 -> 45955 | N16: =sales_data!C417 -> 25 | O16: =sales_data!D417 -> Октябрь | P16: =sales_data!E417 -> Елена | Q16: =sales_data!F417 -> Уфа | R16: =sales_data!G417 -> Приволжский | S16: =sales_data!H417 -> Аксессуары | ... Z16: =sales_data!O417 -> Отменён
L17: =sales_data!A418 -> 2892 | M17: =sales_data!B418 -> 45877 | N17: =sales_data!C418 -> 8 | O17: =sales_data!D418 -> Август | P17: =sales_data!E418 -> Наталья | Q17: =sales_data!F418 -> Воронеж | R17: =sales_data!G418 -> Центральный | S17: =sales_data!H418 -> Аксессуары | ... Z17: =sales_data!O418 -> В пути
L18: =sales_data!A440 -> 4941 | M18: =sales_data!B440 -> 45834 | N18: =sales_data!C440 -> 26 | O18: =sales_data!D440 -> Июнь | P18: =sales_data!E440 -> Борис | Q18: =sales_data!F440 -> Красноярск | R18: =sales_data!G440 -> Сибирский | S18: =sales_data!H440 -> Аксессуары | ... Z18: =sales_data!O440 -> В пути
L19: =sales_data!A471 -> 1545 | M19: =sales_data!B471 -> 45719 | N19: =sales_data!C471 -> 3 | O19: =sales_data!D471 -> Март | P19: =sales_data!E471 -> Ольга | Q19: =sales_data!F471 -> Екатеринбург | R19: =sales_data!G471 -> Уральский | S19: =sales_data!H471 -> Аксессуары | ... Z19: =sales_data!O471 -> В пути
L20: =sales_data!A483 -> 2282 | M20: =sales_data!B483 -> 45672 | N20: =sales_data!C483 -> 15 | O20: =sales_data!D483 -> Январь | P20: =sales_data!E483 -> Игорь | Q20: =sales_data!F483 -> Новосибирск | R20: =sales_data!G483 -> Сибирский | S20: =sales_data!H483 -> Аксессуары | ... Z20: =sales_data!O483 -> В пути
L21: =sales_data!A499 -> 4017 | M21: =sales_data!B499 -> 45806 | N21: =sales_data!C499 -> 29 | O21: =sales_data!D499 -> Май | P21: =sales_data!E499 -> Светлана | Q21: =sales_data!F499 -> Москва | R21: =sales_data!G499 -> Центральный | S21: =sales_data!H499 -> Периферия | ... Z21: =sales_data!O499 -> Отменён
L22: =sales_data!A521 -> 426 | M22: =sales_data!B521 -> 45936 | N22: =sales_data!C521 -> 6 | O22: =sales_data!D521 -> Октябрь | P22: =sales_data!E521 -> Наталья | Q22: =sales_data!F521 -> Челябинск | R22: =sales_data!G521 -> Уральский | S22: =sales_data!H521 -> Периферия | ... Z22: =sales_data!O521 -> Доставлен
L23: =sales_data!A554 -> 2293 | M23: =sales_data!B554 -> 45889 | N23: =sales_data!C554 -> 20 | O23: =sales_data!D554 -> Август | P23: =sales_data!E554 -> Татьяна | Q23: =sales_data!F554 -> Самара | R23: =sales_data!G554 -> Приволжский | S23: =sales_data!H554 -> Аксессуары | ... Z23: =sales_data!O554 -> В пути
L24: =sales_data!A572 -> 3461 | M24: =sales_data!B572 -> 45921 | N24: =sales_data!C572 -> 21 | O24: =sales_data!D572 -> Сентябрь | P24: =sales_data!E572 -> Алексей | Q24: =sales_data!F572 -> Краснодар | R24: =sales_data!G572 -> Южный | S24: =sales_data!H572 -> Периферия | ... Z24: =sales_data!O572 -> Отменён
L25: =sales_data!A574 -> 3484 | M25: =sales_data!B574 -> 45883 | N25: =sales_data!C574 -> 14 | O25: =sales_data!D574 -> Август | P25: =sales_data!E574 -> Мария | Q25: =sales_data!F574 -> Екатеринбург | R25: =sales_data!G574 -> Уральский | S25: =sales_data!H574 -> Аксессуары | ... Z25: =sales_data!O574 -> Отменён
L26: =sales_data!A609 -> 1064 | M26: =sales_data!B609 -> 45780 | N26: =sales_data!C609 -> 3 | O26: =sales_data!D609 -> Май | P26: =sales_data!E609 -> Наталья | Q26: =sales_data!F609 -> Омск | R26: =sales_data!G609 -> Сибирский | S26: =sales_data!H609 -> Аксессуары | ... Z26: =sales_data!O609 -> Доставлен
L27: =sales_data!A651 -> 4800 | M27: =sales_data!B651 -> 46002 | N27: =sales_data!C651 -> 11 | O27: =sales_data!D651 -> Декабрь | P27: =sales_data!E651 -> Владимир | Q27: =sales_data!F651 -> Красноярск | R27: =sales_data!G651 -> Сибирский | S27: =sales_data!H651 -> Аксессуары | ... Z27: =sales_data!O651 -> Доставлен
L28: =sales_data!A660 -> 687 | M28: =sales_data!B660 -> 45981 | N28: =sales_data!C660 -> 20 | O28: =sales_data!D660 -> Ноябрь | P28: =sales_data!E660 -> Ольга | Q28: =sales_data!F660 -> Москва | R28: =sales_data!G660 -> Центральный | S28: =sales_data!H660 -> Периферия | ... Z28: =sales_data!O660 -> В пути
L29: =sales_data!A668 -> 1054 | M29: =sales_data!B668 -> 45777 | N29: =sales_data!C668 -> 30 | O29: =sales_data!D668 -> Апрель | P29: =sales_data!E668 -> Ксения | Q29: =sales_data!F668 -> Нижний Новгород | R29: =sales_data!G668 -> Приволжский | S29: =sales_data!H668 -> Периферия | ... Z29: =sales_data!O668 -> Отменён
L30: =sales_data!A675 -> 1607 | M30: =sales_data!B675 -> 45768 | N30: =sales_data!C675 -> 21 | O30: =sales_data!D675 -> Апрель | P30: =sales_data!E675 -> Елена | Q30: =sales_data!F675 -> Казань | R30: =sales_data!G675 -> Приволжский | S30: =sales_data!H675 -> Периферия | ... Z30: =sales_data!O675 -> В пути
L31: =sales_data!A682 -> 2198 | M31: =sales_data!B682 -> 45843 | N31: =sales_data!C682 -> 5 | O31: =sales_data!D682 -> Июль | P31: =sales_data!E682 -> Алексей | Q31: =sales_data!F682 -> Самара | R31: =sales_data!G682 -> Приволжский | S31: =sales_data!H682 -> Периферия | ... Z31: =sales_data!O682 -> Отменён
L32: =sales_data!A687 -> 2759 | M32: =sales_data!B687 -> 46002 | N32: =sales_data!C687 -> 11 | O32: =sales_data!D687 -> Декабрь | P32: =sales_data!E687 -> Мария | Q32: =sales_data!F687 -> Пермь | R32: =sales_data!G687 -> Приволжский | S32: =sales_data!H687 -> Аксессуары | ... Z32: =sales_data!O687 -> Отменён
L33: =sales_data!A689 -> 2785 | M33: =sales_data!B689 -> 45807 | N33: =sales_data!C689 -> 30 | O33: =sales_data!D689 -> Май | P33: =sales_data!E689 -> Борис | Q33: =sales_data!F689 -> Самара | R33: =sales_data!G689 -> Приволжский | S33: =sales_data!H689 -> Периферия | ... Z33: =sales_data!O689 -> В пути
L34: =sales_data!A729 -> 1153 | M34: =sales_data!B729 -> 45894 | N34: =sales_data!C729 -> 25 | O34: =sales_data!D729 -> Август | P34: =sales_data!E729 -> Борис | Q34: =sales_data!F729 -> Санкт-Петербург | R34: =sales_data!G729 -> Северо-Западный | S34: =sales_data!H729 -> Аксессуары | ... Z34: =sales_data!O729 -> В пути
L35: =sales_data!A793 -> 573 | M35: =sales_data!B793 -> 45739 | N35: =sales_data!C793 -> 23 | O35: =sales_data!D793 -> Март | P35: =sales_data!E793 -> Светлана | Q35: =sales_data!F793 -> Омск | R35: =sales_data!G793 -> Сибирский | S35: =sales_data!H793 -> Аксессуары | ... Z35: =sales_data!O793 -> Доставлен
L36: =sales_data!A824 -> 2706 | M36: =sales_data!B824 -> 45996 | N36: =sales_data!C824 -> 5 | O36: =sales_data!D824 -> Декабрь | P36: =sales_data!E824 -> Наталья | Q36: =sales_data!F824 -> Казань | R36: =sales_data!G824 -> Приволжский | S36: =sales_data!H824 -> Периферия | ... Z36: =sales_data!O824 -> Отменён
L37: =sales_data!A836 -> 3688 | M37: =sales_data!B836 -> 45797 | N37: =sales_data!C836 -> 20 | O37: =sales_data!D836 -> Май | P37: =sales_data!E836 -> Борис | Q37: =sales_data!F836 -> Пермь | R37: =sales_data!G836 -> Приволжский | S37: =sales_data!H836 -> Аксессуары | ... Z37: =sales_data!O836 -> Отменён
L38: =sales_data!A858 -> 1084 | M38: =sales_data!B858 -> 45691 | N38: =sales_data!C858 -> 3 | O38: =sales_data!D858 -> Февраль | P38: =sales_data!E858 -> Светлана | Q38: =sales_data!F858 -> Екатеринбург | R38: =sales_data!G858 -> Уральский | S38: =sales_data!H858 -> Аксессуары | ... Z38: =sales_data!O858 -> Отменён
L39: =sales_data!A879 -> 3749 | M39: =sales_data!B879 -> 45858 | N39: =sales_data!C879 -> 20 | O39: =sales_data!D879 -> Июль | P39: =sales_data!E879 -> Павел | Q39: =sales_data!F879 -> Самара | R39: =sales_data!G879 -> Приволжский | S39: =sales_data!H879 -> Периферия | ... Z39: =sales_data!O879 -> В пути
L40: =sales_data!A895 -> 1234 | M40: =sales_data!B895 -> 46013 | N40: =sales_data!C895 -> 22 | O40: =sales_data!D895 -> Декабрь | P40: =sales_data!E895 -> Алексей | Q40: =sales_data!F895 -> Санкт-Петербург | R40: =sales_data!G895 -> Северо-Западный | S40: =sales_data!H895 -> Аксессуары | ... Z40: =sales_data!O895 -> В пути
L41: =sales_data!A910 -> 2398 | M41: =sales_data!B910 -> 45897 | N41: =sales_data!C910 -> 28 | O41: =sales_data!D910 -> Август | P41: =sales_data!E910 -> Борис | Q41: =sales_data!F910 -> Воронеж | R41: =sales_data!G910 -> Центральный | S41: =sales_data!H910 -> Периферия | ... Z41: =sales_data!O910 -> Отменён
...

Sheet 4_Сортировка
A1: Шаг 4. Сортировка по price по убыванию
A3: order_id | B3: client | C3: city | D3: category | E3: product | F3: quantity | G3: price | H3: manager | I3: channel | J3: price_rank | L3: =sales_data!A2 -> order_id | M3: =sales_data!B2 -> date | N3: =sales_data!C2 -> day | O3: =sales_data!D2 -> month | P3: =sales_data!E2 -> manager | Q3: =sales_data!F2 -> city | R3: =sales_data!G2 -> region | S3: =sales_data!H2 -> category | ... Z3: =sales_data!O2 -> status
A4: 201 | B4: ООО Альфа | C4: Москва | D4: Ноутбуки | E4: Notebook Air | F4: 2 | G4: 55000 | H4: Анна | I4: Онлайн | J4: =RANK(G4,$G$4:$G$12,0)+COUNTIF($G$4:G4,G4)-1 -> 2 | L4: =sales_data!A3 -> 85 | M4: =sales_data!B3 -> 45881 | N4: =sales_data!C3 -> 12 | O4: =sales_data!D3 -> Август | P4: =sales_data!E3 -> Владимир | Q4: =sales_data!F3 -> Уфа | R4: =sales_data!G3 -> Приволжский | S4: =sales_data!H3 -> Аксессуары | ... Z4: =sales_data!O3 -> В пути
A5: 202 | B5: ООО Бета | C5: Санкт-Петербург | D5: Мониторы | E5: Monitor 27 | F5: 1 | G5: 23000 | H5: Борис | I5: Офлайн | J5: =RANK(G5,$G$4:$G$12,0)+COUNTIF($G$4:G5,G5)-1 -> 6 | L5: =sales_data!A4 -> 225 | M5: =sales_data!B4 -> 45697 | N5: =sales_data!C4 -> 9 | O5: =sales_data!D4 -> Февраль | P5: =sales_data!E4 -> Сергей | Q5: =sales_data!F4 -> Казань | R5: =sales_data!G4 -> Приволжский | S5: =sales_data!H4 -> Аксессуары | ... Z5: =sales_data!O4 -> Доставлен
A6: 203 | B6: ИП Гамма | C6: Москва | D6: Ноутбуки | E6: Notebook Pro | F6: 3 | G6: 72000 | H6: Анна | I6: Онлайн | J6: =RANK(G6,$G$4:$G$12,0)+COUNTIF($G$4:G6,G6)-1 -> 1 | L6: =sales_data!A5 -> 332 | M6: =sales_data!B5 -> 45941 | N6: =sales_data!C5 -> 11 | O6: =sales_data!D5 -> Октябрь | P6: =sales_data!E5 -> Борис | Q6: =sales_data!F5 -> Омск | R6: =sales_data!G5 -> Сибирский | S6: =sales_data!H5 -> Аксессуары | ... Z6: =sales_data!O5 -> В пути
A7: 204 | B7: ООО Дельта | C7: Казань | D7: Периферия | E7: Mouse Pro | F7: 5 | G7: 2500 | H7: Виктор | I7: Маркетплейс | J7: =RANK(G7,$G$4:$G$12,0)+COUNTIF($G$4:G7,G7)-1 -> 9 | L7: =sales_data!A6 -> 430 | M7: =sales_data!B6 -> 45746 | N7: =sales_data!C6 -> 30 | O7: =sales_data!D6 -> Март | P7: =sales_data!E6 -> Светлана | Q7: =sales_data!F6 -> Новосибирск | R7: =sales_data!G6 -> Сибирский | S7: =sales_data!H6 -> Аксессуары | ... Z7: =sales_data!O6 -> Отменён
A8: 205 | B8: ООО Эпсилон | C8: Москва | D8: Мониторы | E8: Monitor 24 | F8: 2 | G8: 18000 | H8: Анна | I8: Онлайн | J8: =RANK(G8,$G$4:$G$12,0)+COUNTIF($G$4:G8,G8)-1 -> 7 | L8: =sales_data!A7 -> 459 | M8: =sales_data!B7 -> 45856 | N8: =sales_data!C7 -> 18 | O8: =sales_data!D7 -> Июль | P8: =sales_data!E7 -> Мария | Q8: =sales_data!F7 -> Нижний Новгород | R8: =sales_data!G7 -> Приволжский | S8: =sales_data!H7 -> Аксессуары | ... Z8: =sales_data!O7 -> Доставлен
A9: 206 | B9: ИП Жасмин | C9: Екатеринбург | D9: Ноутбуки | E9: Notebook Lite | F9: 1 | G9: 49000 | H9: Борис | I9: Офлайн | J9: =RANK(G9,$G$4:$G$12,0)+COUNTIF($G$4:G9,G9)-1 -> 4 | L9: =sales_data!A8 -> 570 | M9: =sales_data!B8 -> 45766 | N9: =sales_data!C8 -> 19 | O9: =sales_data!D8 -> Апрель | P9: =sales_data!E8 -> Ксения | Q9: =sales_data!F8 -> Москва | R9: =sales_data!G8 -> Центральный | S9: =sales_data!H8 -> Аксессуары | ... Z9: =sales_data!O8 -> В пути
A10: 207 | B10: ООО Зета | C10: Москва | D10: Периферия | E10: Keyboard X | F10: 4 | G10: 4000 | H10: Виктор | I10: Онлайн | J10: =RANK(G10,$G$4:$G$12,0)+COUNTIF($G$4:G10,G10)-1 -> 8 | L10: =sales_data!A9 -> 639 | M10: =sales_data!B9 -> 45901 | N10: =sales_data!C9 -> 1 | O10: =sales_data!D9 -> Сентябрь | P10: =sales_data!E9 -> Павел | Q10: =sales_data!F9 -> Пермь | R10: =sales_data!G9 -> Приволжский | S10: =sales_data!H9 -> Аксессуары | ... Z10: =sales_data!O9 -> Отменён
A11: 208 | B11: ООО Ита | C11: Новосибирск | D11: Ноутбуки | E11: Notebook Air | F11: 2 | G11: 55000 | H11: Анна | I11: Маркетплейс | J11: =RANK(G11,$G$4:$G$12,0)+COUNTIF($G$4:G11,G11)-1 -> 3 | L11: =sales_data!A10 -> 665 | M11: =sales_data!B10 -> 45809 | N11: =sales_data!C10 -> 1 | O11: =sales_data!D10 -> Июнь | P11: =sales_data!E10 -> Владимир | Q11: =sales_data!F10 -> Екатеринбург | R11: =sales_data!G10 -> Уральский | S11: =sales_data!H10 -> Аксессуары | ... Z11: =sales_data!O10 -> Отменён
A12: 209 | B12: ООО Каппа | C12: Москва | D12: Ноутбуки | E12: Notebook Start | F12: 1 | G12: 43000 | H12: Борис | I12: Офлайн | J12: =RANK(G12,$G$4:$G$12,0)+COUNTIF($G$4:G12,G12)-1 -> 5 | L12: =sales_data!A11 -> 746 | M12: =sales_data!B11 -> 45979 | N12: =sales_data!C11 -> 18 | O12: =sales_data!D11 -> Ноябрь | P12: =sales_data!E11 -> Павел | Q12: =sales_data!F11 -> Воронеж | R12: =sales_data!G11 -> Центральный | S12: =sales_data!H11 -> Аксессуары | ... Z12: =sales_data!O11 -> Отменён
L13: =sales_data!A12 -> 1035 | M13: =sales_data!B12 -> 45812 | N13: =sales_data!C12 -> 4 | O13: =sales_data!D12 -> Июнь | P13: =sales_data!E12 -> Борис | Q13: =sales_data!F12 -> Москва | R13: =sales_data!G12 -> Центральный | S13: =sales_data!H12 -> Аксессуары | ... Z13: =sales_data!O12 -> Доставлен
L14: =sales_data!A13 -> 1562 | M14: =sales_data!B13 -> 45696 | N14: =sales_data!C13 -> 8 | O14: =sales_data!D13 -> Февраль | P14: =sales_data!E13 -> Игорь | Q14: =sales_data!F13 -> Казань | R14: =sales_data!G13 -> Приволжский | S14: =sales_data!H13 -> Аксессуары | ... Z14: =sales_data!O13 -> Отменён
L15: =sales_data!A14 -> 1720 | M15: =sales_data!B14 -> 45786 | N15: =sales_data!C14 -> 9 | O15: =sales_data!D14 -> Май | P15: =sales_data!E14 -> Наталья | Q15: =sales_data!F14 -> Нижний Новгород | R15: =sales_data!G14 -> Приволжский | S15: =sales_data!H14 -> Аксессуары | ... Z15: =sales_data!O14 -> В пути
L16: =sales_data!A15 -> 1722 | M16: =sales_data!B15 -> 45798 | N16: =sales_data!C15 -> 21 | O16: =sales_data!D15 -> Май | P16: =sales_data!E15 -> Татьяна | Q16: =sales_data!F15 -> Самара | R16: =sales_data!G15 -> Приволжский | S16: =sales_data!H15 -> Аксессуары | ... Z16: =sales_data!O15 -> В пути
L17: =sales_data!A16 -> 1736 | M17: =sales_data!B16 -> 45985 | N17: =sales_data!C16 -> 24 | O17: =sales_data!D16 -> Ноябрь | P17: =sales_data!E16 -> Игорь | Q17: =sales_data!F16 -> Екатеринбург | R17: =sales_data!G16 -> Уральский | S17: =sales_data!H16 -> Аксессуары | ... Z17: =sales_data!O16 -> В пути
L18: =sales_data!A17 -> 1872 | M18: =sales_data!B17 -> 45779 | N18: =sales_data!C17 -> 2 | O18: =sales_data!D17 -> Май | P18: =sales_data!E17 -> Татьяна | Q18: =sales_data!F17 -> Челябинск | R18: =sales_data!G17 -> Уральский | S18: =sales_data!H17 -> Аксессуары | ... Z18: =sales_data!O17 -> В пути
L19: =sales_data!A18 -> 1950 | M19: =sales_data!B18 -> 45736 | N19: =sales_data!C18 -> 20 | O19: =sales_data!D18 -> Март | P19: =sales_data!E18 -> Владимир | Q19: =sales_data!F18 -> Казань | R19: =sales_data!G18 -> Приволжский | S19: =sales_data!H18 -> Аксессуары | ... Z19: =sales_data!O18 -> Доставлен
L20: =sales_data!A19 -> 2086 | M20: =sales_data!B19 -> 45742 | N20: =sales_data!C19 -> 26 | O20: =sales_data!D19 -> Март | P20: =sales_data!E19 -> Игорь | Q20: =sales_data!F19 -> Казань | R20: =sales_data!G19 -> Приволжский | S20: =sales_data!H19 -> Аксессуары | ... Z20: =sales_data!O19 -> Доставлен
L21: =sales_data!A20 -> 2264 | M21: =sales_data!B20 -> 45911 | N21: =sales_data!C20 -> 11 | O21: =sales_data!D20 -> Сентябрь | P21: =sales_data!E20 -> Павел | Q21: =sales_data!F20 -> Челябинск | R21: =sales_data!G20 -> Уральский | S21: =sales_data!H20 -> Аксессуары | ... Z21: =sales_data!O20 -> Отменён
L22: =sales_data!A21 -> 2345 | M22: =sales_data!B21 -> 45934 | N22: =sales_data!C21 -> 4 | O22: =sales_data!D21 -> Октябрь | P22: =sales_data!E21 -> Дмитрий | Q22: =sales_data!F21 -> Краснодар | R22: =sales_data!G21 -> Южный | S22: =sales_data!H21 -> Аксессуары | ... Z22: =sales_data!O21 -> В пути
L23: =sales_data!A22 -> 2401 | M23: =sales_data!B22 -> 45969 | N23: =sales_data!C22 -> 8 | O23: =sales_data!D22 -> Ноябрь | P23: =sales_data!E22 -> Мария | Q23: =sales_data!F22 -> Москва | R23: =sales_data!G22 -> Центральный | S23: =sales_data!H22 -> Аксессуары | ... Z23: =sales_data!O22 -> Отменён
L24: =sales_data!A23 -> 2552 | M24: =sales_data!B23 -> 45973 | N24: =sales_data!C23 -> 12 | O24: =sales_data!D23 -> Ноябрь | P24: =sales_data!E23 -> Ксения | Q24: =sales_data!F23 -> Казань | R24: =sales_data!G23 -> Приволжский | S24: =sales_data!H23 -> Аксессуары | ... Z24: =sales_data!O23 -> Отменён
L25: =sales_data!A24 -> 2711 | M25: =sales_data!B24 -> 45964 | N25: =sales_data!C24 -> 3 | O25: =sales_data!D24 -> Ноябрь | P25: =sales_data!E24 -> Анна | Q25: =sales_data!F24 -> Красноярск | R25: =sales_data!G24 -> Сибирский | S25: =sales_data!H24 -> Аксессуары | ... Z25: =sales_data!O24 -> Отменён

Sheet 5_Новые_столбцы
A1: Шаг 5. Создаём столбец revenue и ищем крупные заказы
A3: order_id | B3: client | C3: city | D3: category | E3: product | F3: quantity | G3: price | H3: manager | I3: channel | J3: revenue | K3: big_order | M3: Топ-5 по revenue
A4: 201 | B4: ООО Альфа | C4: Москва | D4: Ноутбуки | E4: Notebook Air | F4: 2 | G4: 55000 | H4: Анна | I4: Онлайн | J4: =F4*G4 -> 110000 | K4: =IF(J4>=100000,"Крупный заказ","Обычный") -> Крупный заказ | M4: order_id | N4: date | O4: day | P4: month | Q4: manager | R4: city | S4: region | T4: category | U4: product | V4: client_type | W4: quantity | X4: price_per_unit | Y4: revenue | Z4: channel | AA4: status
A5: 202 | B5: ООО Бета | C5: Санкт-Петербург | D5: Мониторы | E5: Monitor 27 | F5: 1 | G5: 23000 | H5: Борис | I5: Офлайн | J5: =F5*G5 -> 23000 | K5: =IF(J5>=100000,"Крупный заказ","Обычный") -> Обычный | M5: =sales_data!A2 -> order_id | N5: =sales_data!B2 -> date | O5: =sales_data!C2 -> day | P5: =sales_data!D2 -> month | Q5: =sales_data!E2 -> manager | R5: =sales_data!F2 -> city | S5: =sales_data!G2 -> region | T5: =sales_data!H2 -> category | ... AA5: =sales_data!O2 -> status
A6: 203 | B6: ИП Гамма | C6: Москва | D6: Ноутбуки | E6: Notebook Pro | F6: 3 | G6: 72000 | H6: Анна | I6: Онлайн | J6: =F6*G6 -> 216000 | K6: =IF(J6>=100000,"Крупный заказ","Обычный") -> Крупный заказ | M6: =sales_data!A4892 -> 2981 | N6: =sales_data!B4892 -> 45991 | O6: =sales_data!C4892 -> 30 | P6: =sales_data!D4892 -> Ноябрь | Q6: =sales_data!E4892 -> Павел | R6: =sales_data!F4892 -> Самара | S6: =sales_data!G4892 -> Приволжский | T6: =sales_data!H4892 -> Серверы | ... AA6: =sales_data!O4892 -> Доставлен
A7: 204 | B7: ООО Дельта | C7: Казань | D7: Периферия | E7: Mouse Pro | F7: 5 | G7: 2500 | H7: Виктор | I7: Маркетплейс | J7: =F7*G7 -> 12500 | K7: =IF(J7>=100000,"Крупный заказ","Обычный") -> Обычный | M7: =sales_data!A4912 -> 2930 | N7: =sales_data!B4912 -> 45820 | O7: =sales_data!C4912 -> 12 | P7: =sales_data!D4912 -> Июнь | Q7: =sales_data!E4912 -> Наталья | R7: =sales_data!F4912 -> Санкт-Петербург | S7: =sales_data!G4912 -> Северо-Западный | T7: =sales_data!H4912 -> Серверы | ... AA7: =sales_data!O4912 -> В пути
A8: 205 | B8: ООО Эпсилон | C8: Москва | D8: Мониторы | E8: Monitor 24 | F8: 2 | G8: 18000 | H8: Анна | I8: Онлайн | J8: =F8*G8 -> 36000 | K8: =IF(J8>=100000,"Крупный заказ","Обычный") -> Обычный | M8: =sales_data!A4915 -> 1711 | N8: =sales_data!B4915 -> 45926 | O8: =sales_data!C4915 -> 26 | P8: =sales_data!D4915 -> Сентябрь | Q8: =sales_data!E4915 -> Ксения | R8: =sales_data!F4915 -> Новосибирск | S8: =sales_data!G4915 -> Сибирский | T8: =sales_data!H4915 -> Серверы | ... AA8: =sales_data!O4915 -> В пути
A9: 206 | B9: ИП Жасмин | C9: Екатеринбург | D9: Ноутбуки | E9: Notebook Lite | F9: 1 | G9: 49000 | H9: Борис | I9: Офлайн | J9: =F9*G9 -> 49000 | K9: =IF(J9>=100000,"Крупный заказ","Обычный") -> Обычный | M9: =sales_data!A4920 -> 1388 | N9: =sales_data!B4920 -> 45853 | O9: =sales_data!C4920 -> 15 | P9: =sales_data!D4920 -> Июль | Q9: =sales_data!E4920 -> Анна | R9: =sales_data!F4920 -> Уфа | S9: =sales_data!G4920 -> Приволжский | T9: =sales_data!H4920 -> Серверы | ... AA9: =sales_data!O4920 -> Доставлен
A10: 207 | B10: ООО Зета | C10: Москва | D10: Периферия | E10: Keyboard X | F10: 4 | G10: 4000 | H10: Виктор | I10: Онлайн | J10: =F10*G10 -> 16000 | K10: =IF(J10>=100000,"Крупный заказ","Обычный") -> Обычный | M10: =sales_data!A4931 -> 2176 | N10: =sales_data!B4931 -> 45718 | O10: =sales_data!C4931 -> 2 | P10: =sales_data!D4931 -> Март | Q10: =sales_data!E4931 -> Алексей | R10: =sales_data!F4931 -> Воронеж | S10: =sales_data!G4931 -> Центральный | T10: =sales_data!H4931 -> Серверы | ... AA10: =sales_data!O4931 -> Отменён
A11: 208 | B11: ООО Ита | C11: Новосибирск | D11: Ноутбуки | E11: Notebook Air | F11: 2 | G11: 55000 | H11: Анна | I11: Маркетплейс | J11: =F11*G11 -> 110000 | K11: =IF(J11>=100000,"Крупный заказ","Обычный") -> Крупный заказ | M11: Количество крупных заказов | N11: 5
A12: 209 | B12: ООО Каппа | C12: Москва | D12: Ноутбуки | E12: Notebook Start | F12: 1 | G12: 43000 | H12: Борис | I12: Офлайн | J12: =F12*G12 -> 43000 | K12: =IF(J12>=100000,"Крупный заказ","Обычный") -> Обычный

Sheet 6_Тест
A1: Тест по занятию 8
A3: Вопрос | B3: Правильный ответ | C3: Подсказка
A4: Сколько строк в исходной таблице? | B4: 5000 | C4: Аналог df.shape[0]
A5: Сколько заказов попадает в фильтр category == "Ноутбуки"? | B5: 813 | C5: Смотрите sheet 2 или notebook cell 2
A6: Сколько заказов попадает в фильтр city == "Москва" и channel == "Онлайн"? | B6: 156 | C6: Используйте AND в Excel и & в pandas
A7: Какая общая выручка после создания столбца revenue? | B7: 2612584200 | C7: Это сумма quantity * price
A8: Сколько крупных заказов с revenue >= 100000? | B8: 2763 | C8: Смотрите столбец big_order
